Workbook

Sheet S1 Lun-Mié
B1: ← Volver al índice
B2: Primer Semestre Galápagos 2026-2027 · Materias de semestre completo (Lun-Mié) | K2: RESUMEN DEL MÓDULO
B3: Materias de semestre completo · dos sesiones semanales de 1.5 h · 17-ago-2026 al 11-dic-2026. | K3: Sesiones de clase | L3: =COUNTIF(F12:F45,"Clase") -> 31
B4: Evaluación docente por parte de estudiantes (202610-G4 (fin de semestre)): del 07-dic-2026 al 10-dic-2026 — cierra antes del último día de clase. | K4: Sesiones asincrónicas | L4: =COUNTIF(F12:F45,"Asincrónico") -> 0
K5: Días sin clase (feriado / receso) | L5: =COUNTIF(F12:F45,"FERIADO")+COUNTIF(F12:F45,"RECESO") -> 3
K6: Semanas | L6: =MAX(B12:B45) -> 17
K7: Evaluación docente | L7: ="07-dic-2026 al 10-dic-2026" -> 07-dic-2026 al 10-dic-2026
B9: Cronograma ADM 2003 Análisis de Datos · versión Python con apoyo de IA (cronograma v2). Semana 11 comprimida en una sesión por el feriado del 2-nov.
B11: Semana | C11: N° Sesión | D11: Fecha | E11: Día | F11: Estado | G11: Tema | H11: Entregas | I11: Observación
B12: 1 | C12: =IF(OR(F12="FERIADO",F12="RECESO"),"—",ROWS($F$12:F12)-COUNTIF($F$12:F12,"FERIADO")-COUNTIF($F$12:F12,"RECESO")) -> 1 | D12: 17-ago-2026 | E12: Lunes | F12: Clase | G12: S1 · Por qué fracasan los análisis | H12: Presentación del curso y del proyecto integrador. Firma del contrato de grupo.
B13: 1 | C13: =IF(OR(F13="FERIADO",F13="RECESO"),"—",ROWS($F$12:F13)-COUNTIF($F$12:F13,"FERIADO")-COUNTIF($F$12:F13,"RECESO")) -> 2 | D13: 19-ago-2026 | E13: Miércoles | F13: Clase | G13: S1 · Colab y el primer cuaderno | H13: Contrato de grupo firmado. DataCamp: Understanding Data Science.
B14: 2 | C14: =IF(OR(F14="FERIADO",F14="RECESO"),"—",ROWS($F$12:F14)-COUNTIF($F$12:F14,"FERIADO")-COUNTIF($F$12:F14,"RECESO")) -> 3 | D14: 24-ago-2026 | E14: Lunes | F14: Clase | G14: S2 · Unidad de análisis, métrica, comparación y decisión
B15: 2 | C15: =IF(OR(F15="FERIADO",F15="RECESO"),"—",ROWS($F$12:F15)-COUNTIF($F$12:F15,"FERIADO")-COUNTIF($F$12:F15,"RECESO")) -> 4 | D15: 26-ago-2026 | E15: Miércoles | F15: Clase | G15: S2 · Carga y primer contacto con la base del curso | H15: Deber 1: ficha de análisis de una página, sin código.
B16: 3 | C16: =IF(OR(F16="FERIADO",F16="RECESO"),"—",ROWS($F$12:F16)-COUNTIF($F$12:F16,"FERIADO")-COUNTIF($F$12:F16,"RECESO")) -> 5 | D16: 31-ago-2026 | E16: Lunes | F16: Clase | G16: S3 · La trampa del promedio
B17: 3 | C17: =IF(OR(F17="FERIADO",F17="RECESO"),"—",ROWS($F$12:F17)-COUNTIF($F$12:F17,"FERIADO")-COUNTIF($F$12:F17,"RECESO")) -> 6 | D17: 02-sep-2026 | E17: Miércoles | F17: Clase | G17: S3 · Perfilado descriptivo contra reloj | H17: DataCamp: Introduction to Python.
B18: 4 | C18: =IF(OR(F18="FERIADO",F18="RECESO"),"—",ROWS($F$12:F18)-COUNTIF($F$12:F18,"FERIADO")-COUNTIF($F$12:F18,"RECESO")) -> 7 | D18: 07-sep-2026 | E18: Lunes | F18: Clase | G18: S4 · Granularidad, tipos de dato y calidad
B19: 4 | C19: =IF(OR(F19="FERIADO",F19="RECESO"),"—",ROWS($F$12:F19)-COUNTIF($F$12:F19,"FERIADO")-COUNTIF($F$12:F19,"RECESO")) -> 8 | D19: 09-sep-2026 | E19: Miércoles | F19: Clase | G19: S4 · Inventario de problemas de calidad | H19: Deber 2: bitácora de limpieza. Propuesta de proyecto final.
B20: 5 | C20: =IF(OR(F20="FERIADO",F20="RECESO"),"—",ROWS($F$12:F20)-COUNTIF($F$12:F20,"FERIADO")-COUNTIF($F$12:F20,"RECESO")) -> 9 | D20: 14-sep-2026 | E20: Lunes | F20: Clase | G20: S5 · Dividir, aplicar y recombinar. Uniones y cardinalidad
B21: 5 | C21: =IF(OR(F21="FERIADO",F21="RECESO"),"—",ROWS($F$12:F21)-COUNTIF($F$12:F21,"FERIADO")-COUNTIF($F$12:F21,"RECESO")) -> 10 | D21: 16-sep-2026 | E21: Miércoles | F21: Clase | G21: S5 · Torneo de preguntas y tabla de indicadores | H21: Deber 3: tabla de indicadores reproducible. DataCamp: Data Manipulation with pandas y Joining Data with pandas.
B22: 6 | C22: =IF(OR(F22="FERIADO",F22="RECESO"),"—",ROWS($F$12:F22)-COUNTIF($F$12:F22,"FERIADO")-COUNTIF($F$12:F22,"RECESO")) -> 11 | D22: 21-sep-2026 | E22: Lunes | F22: Clase | G22: S6 · Explorar, verificar y comunicar | H22: Lectura previa: Storytelling con datos (Knaflic).
B23: 6 | C23: =IF(OR(F23="FERIADO",F23="RECESO"),"—",ROWS($F$12:F23)-COUNTIF($F$12:F23,"FERIADO")-COUNTIF($F$12:F23,"RECESO")) -> 12 | D23: 23-sep-2026 | E23: Miércoles | F23: Clase | G23: S6 · Clínica de rediseño | H23: Deber 4: tres gráficos anotados del negocio. DataCamp: Introduction to Data Visualization with Matplotlib.
B24: 7 | C24: =IF(OR(F24="FERIADO",F24="RECESO"),"—",ROWS($F$12:F24)-COUNTIF($F$12:F24,"FERIADO")-COUNTIF($F$12:F24,"RECESO")) -> 13 | D24: 28-sep-2026 | E24: Lunes | F24: Clase | G24: S7 · Del gráfico al tablero
B25: 7 | C25: =IF(OR(F25="FERIADO",F25="RECESO"),"—",ROWS($F$12:F25)-COUNTIF($F$12:F25,"FERIADO")-COUNTIF($F$12:F25,"RECESO")) -> 14 | D25: 30-sep-2026 | E25: Miércoles | F25: Clase | G25: S7 · Construcción del tablero del proyecto | H25: Tablero interactivo entregado dentro del cuaderno.
B26: 8 | C26: =IF(OR(F26="FERIADO",F26="RECESO"),"—",ROWS($F$12:F26)-COUNTIF($F$12:F26,"FERIADO")-COUNTIF($F$12:F26,"RECESO")) -> 15 | D26: 05-oct-2026 | E26: Lunes | F26: Clase | G26: S8 · Quién es un cliente valioso
B27: 8 | C27: =IF(OR(F27="FERIADO",F27="RECESO"),"—",ROWS($F$12:F27)-COUNTIF($F$12:F27,"FERIADO")-COUNTIF($F$12:F27,"RECESO")) -> 16 | D27: 07-oct-2026 | E27: Miércoles | F27: Clase | G27: S8 · Segmentar, nombrar y accionar | H27: PROYECTO DE MEDIO SEMESTRE: análisis RFM+P con recomendación comercial por segmento. Se entrega durante el receso. DataCamp: Unsupervised Learning in Python.
B28: 9 | C28: =IF(OR(F28="FERIADO",F28="RECESO"),"—",ROWS($F$12:F28)-COUNTIF($F$12:F28,"FERIADO")-COUNTIF($F$12:F28,"RECESO")) -> — | D28: 12-oct-2026 | E28: Lunes | F28: RECESO | I28: Receso académico de medio semestre y Feriado Independencia de Guayaquil
B29: 9 | C29: =IF(OR(F29="FERIADO",F29="RECESO"),"—",ROWS($F$12:F29)-COUNTIF($F$12:F29,"FERIADO")-COUNTIF($F$12:F29,"RECESO")) -> — | D29: 14-oct-2026 | E29: Miércoles | F29: RECESO | I29: Receso académico de medio semestre y Feriado Independencia de Guayaquil
B30: 10 | C30: =IF(OR(F30="FERIADO",F30="RECESO"),"—",ROWS($F$12:F30)-COUNTIF($F$12:F30,"FERIADO")-COUNTIF($F$12:F30,"RECESO")) -> 17 | D30: 19-oct-2026 | E30: Lunes | F30: Clase | G30: S9 · Comparado con qué | H30: Devolución del proyecto de medio semestre.
B31: 10 | C31: =IF(OR(F31="FERIADO",F31="RECESO"),"—",ROWS($F$12:F31)-COUNTIF($F$12:F31,"FERIADO")-COUNTIF($F$12:F31,"RECESO")) -> 18 | D31: 21-oct-2026 | E31: Miércoles | F31: Clase | G31: S9 · Pruebas estadísticas y diseño experimental | H31: Deber 5: diseño experimental de una página.
B32: 11 | C32: =IF(OR(F32="FERIADO",F32="RECESO"),"—",ROWS($F$12:F32)-COUNTIF($F$12:F32,"FERIADO")-COUNTIF($F$12:F32,"RECESO")) -> 19 | D32: 26-oct-2026 | E32: Lunes | F32: Clase | G32: S10 · De la eficiencia al modelo de negocio
B33: 11 | C33: =IF(OR(F33="FERIADO",F33="RECESO"),"—",ROWS($F$12:F33)-COUNTIF($F$12:F33,"FERIADO")-COUNTIF($F$12:F33,"RECESO")) -> 20 | D33: 28-oct-2026 | E33: Miércoles | F33: Clase | G33: S10 · Customer journey map y service blueprint | H33: Journey map y blueprint anotados con los puntos de captura de datos.
B34: 12 | C34: =IF(OR(F34="FERIADO",F34="RECESO"),"—",ROWS($F$12:F34)-COUNTIF($F$12:F34,"FERIADO")-COUNTIF($F$12:F34,"RECESO")) -> — | D34: 02-nov-2026 | E34: Lunes | F34: FERIADO | I34: Feriado Día de Difuntos e Independencia de Cuenca
B35: 12 | C35: =IF(OR(F35="FERIADO",F35="RECESO"),"—",ROWS($F$12:F35)-COUNTIF($F$12:F35,"FERIADO")-COUNTIF($F$12:F35,"RECESO")) -> 21 | D35: 04-nov-2026 | E35: Miércoles | F35: Clase | G35: S11 · Semana comprimida · El mapa de los modelos y la ecuación de valor | H35: Evaluación intermedia sobre criterio de negocio.
B36: 13 | C36: =IF(OR(F36="FERIADO",F36="RECESO"),"—",ROWS($F$12:F36)-COUNTIF($F$12:F36,"FERIADO")-COUNTIF($F$12:F36,"RECESO")) -> 22 | D36: 09-nov-2026 | E36: Lunes | F36: Clase | G36: S12 · Una variable explica otra
B37: 13 | C37: =IF(OR(F37="FERIADO",F37="RECESO"),"—",ROWS($F$12:F37)-COUNTIF($F$12:F37,"FERIADO")-COUNTIF($F$12:F37,"RECESO")) -> 23 | D37: 11-nov-2026 | E37: Miércoles | F37: Clase | G37: S12 · Pronóstico con línea base | H37: Deber 6: pronóstico con línea base declarada. DataCamp: Introduction to Regression with statsmodels.
B38: 14 | C38: =IF(OR(F38="FERIADO",F38="RECESO"),"—",ROWS($F$12:F38)-COUNTIF($F$12:F38,"FERIADO")-COUNTIF($F$12:F38,"RECESO")) -> 24 | D38: 16-nov-2026 | E38: Lunes | F38: Clase | G38: S13 · Varias variables a la vez
B39: 14 | C39: =IF(OR(F39="FERIADO",F39="RECESO"),"—",ROWS($F$12:F39)-COUNTIF($F$12:F39,"FERIADO")-COUNTIF($F$12:F39,"RECESO")) -> 25 | D39: 18-nov-2026 | E39: Miércoles | F39: Clase | G39: S13 · Modelo múltiple del negocio | H39: Avance de proyecto: modelo de pronóstico documentado.
B40: 15 | C40: =IF(OR(F40="FERIADO",F40="RECESO"),"—",ROWS($F$12:F40)-COUNTIF($F$12:F40,"FERIADO")-COUNTIF($F$12:F40,"RECESO")) -> 26 | D40: 23-nov-2026 | E40: Lunes | F40: Clase | G40: S14 · Probabilidad como recurso de focalización
B41: 15 | C41: =IF(OR(F41="FERIADO",F41="RECESO"),"—",ROWS($F$12:F41)-COUNTIF($F$12:F41,"FERIADO")-COUNTIF($F$12:F41,"RECESO")) -> 27 | D41: 25-nov-2026 | E41: Miércoles | F41: Clase | G41: S14 · Focalización con presupuesto limitado | H41: Deber 7: recomendación de focalización con retorno esperado. DataCamp: Supervised Learning with scikit-learn.
B42: 16 | C42: =IF(OR(F42="FERIADO",F42="RECESO"),"—",ROWS($F$12:F42)-COUNTIF($F$12:F42,"FERIADO")-COUNTIF($F$12:F42,"RECESO")) -> 28 | D42: 30-nov-2026 | E42: Lunes | F42: Clase | G42: S15 · Un modelo aprende del pasado y reproduce sus desigualdades
...

Sheet Detalle por sesión
A1: Sesión | B1: Fecha | C1: Día | D1: Semana curso | E1: Bloque | F1: Tema | G1: Desarrollo de la sesión | H1: Entrega | I1: Material del seminario de Python
A2: 1 | B2: 17-ago-2026 | C2: Lunes | D2: 1 | E2: I · Leer datos | F2: Por qué fracasan los análisis | G2: Un informe real con datos correctos y conclusión inválida. La escalera descriptivo, diagnóstico, predictivo y prescriptivo. Qué se califica en este curso: el encargo y la verificación, no el código. | H2: Presentación del curso y del proyecto integrador. Firma del contrato de grupo.
A3: 2 | B3: 19-ago-2026 | C3: Miércoles | D3: 1 | E3: I · Leer datos | F3: Colab y el primer cuaderno | G3: Recorrido guiado de un análisis completo de principio a fin, de la pregunta a la recomendación. Firma del protocolo de uso de IA generativa y apertura de la bitácora de prompts. | H3: Contrato de grupo firmado. DataCamp: Understanding Data Science. | I3: S01-C1 · Kick-off del seminario · clase_01.ipynb
A4: 3 | B4: 24-ago-2026 | C4: Lunes | D4: 2 | E4: I · Leer datos | F4: Unidad de análisis, métrica, comparación y decisión | G4: Clínica de definiciones ambiguas: qué es un cliente activo, qué cuenta como venta, qué es un pedido. Caso de apertura del semestre.
A5: 4 | B5: 26-ago-2026 | C5: Miércoles | D5: 2 | E5: I · Leer datos | F5: Carga y primer contacto con la base del curso | G5: read_csv, head, info y shape. Cada grupo redacta la ficha de análisis de su proyecto y otro grupo la ataca. | H5: Deber 1: ficha de análisis de una página, sin código. | I5: S03-C2 · Pandas I · clase_06.ipynb · S02-C2 · Planteamiento del proyecto · clase_04.ipynb
A6: 5 | B6: 31-ago-2026 | C6: Lunes | D6: 3 | E6: I · Leer datos | F6: La trampa del promedio | G6: Distribuciones bimodales, mediana frente a media, dispersión y tamaño de muestra. Caso: dos áreas reportan ventas distintas del mismo mes.
A7: 6 | B7: 02-sep-2026 | C7: Miércoles | D7: 3 | E7: I · Leer datos | F7: Perfilado descriptivo contra reloj | G7: describe, value_counts y quantile. Doce preguntas descriptivas de dificultad creciente sobre la base del curso. | H7: DataCamp: Introduction to Python. | I7: S04-C2 · Visualizaciones · clase_08.ipynb (secciones 1-3)
A8: 7 | B8: 07-sep-2026 | C8: Lunes | D8: 4 | E8: I · Leer datos | F8: Granularidad, tipos de dato y calidad | G8: La diferencia entre ausente, cero y desconocido. Caso: el diez por ciento de las transacciones no tiene identificador de cliente.
A9: 8 | B9: 09-sep-2026 | C9: Miércoles | D9: 4 | E9: I · Leer datos | F9: Inventario de problemas de calidad | G9: dtypes, isna, duplicated y astype. Cuantificación de cada problema y decisión de limpieza documentada. | H9: Deber 2: bitácora de limpieza. Propuesta de proyecto final. | I9: S04-C1 · Pandas II · clase_07.ipynb (bloque de limpieza)
A10: 9 | B10: 14-sep-2026 | C10: Lunes | D10: 5 | E10: I · Leer datos | F10: Dividir, aplicar y recombinar. Uniones y cardinalidad | G10: El patrón groupby y agg. Los cuatro tipos de unión. El error que llega a un directorio: una unión que duplica filas e infla la facturación.
A11: 10 | B11: 16-sep-2026 | C11: Miércoles | D11: 5 | E11: I · Leer datos | F11: Torneo de preguntas y tabla de indicadores | G11: Cada grupo formula tres preguntas de negocio y otro las responde con datos. Construcción de la tabla mensual de indicadores desde cuatro fuentes, cuadrada contra una cifra de control. | H11: Deber 3: tabla de indicadores reproducible. DataCamp: Data Manipulation with pandas y Joining Data with pandas. | I11: S04-C1 · Pandas II · clase_07.ipynb (bloque de agrupación)
A12: 11 | B12: 21-sep-2026 | C12: Lunes | D12: 6 | E12: II · Comunicar datos | F12: Explorar, verificar y comunicar | G12: Cuarteto de Anscombe. Repertorio mínimo de gráficos, ejes, escalas y el título que lleva la conclusión. Reglas de honestidad visual. | H12: Lectura previa: Storytelling con datos (Knaflic).
A13: 12 | B13: 23-sep-2026 | C13: Miércoles | D13: 6 | E13: II · Comunicar datos | F13: Clínica de rediseño | G13: matplotlib y seaborn. Cada grupo toma un gráfico malo publicado y lo rediseña justificando cada cambio. | H13: Deber 4: tres gráficos anotados del negocio. DataCamp: Introduction to Data Visualization with Matplotlib. | I13: S04-C2 · Visualizaciones · clase_08.ipynb (secciones 4-7) · Material Actual/Actividades Organizadas/99_Lecturas_y_Material_de_Apoyo/CONTEXTO - Storytelling con datos - Cole Nussbaumer Knaflic (1).pdf
A14: 13 | B14: 28-sep-2026 | C14: Lunes | D14: 7 | E14: II · Comunicar datos | F14: Del gráfico al tablero | G14: Interactividad, jerarquía visual y qué se elimina. Fondo blanco y ausencia de decoración. El estado de resultados contado a no financieros.
A15: 14 | B15: 30-sep-2026 | C15: Miércoles | D15: 7 | E15: II · Comunicar datos | F15: Construcción del tablero del proyecto | G15: Plotly y Streamlit. Cada grupo contesta una pregunta gerencial con su tablero y recibe fuego cruzado. | H15: Tablero interactivo entregado dentro del cuaderno. | I15: S08-C1 · Dashboards con Streamlit · clase_15.ipynb
A16: 15 | B16: 05-oct-2026 | C16: Lunes | D16: 8 | E16: Corte de medio semestre | F16: Quién es un cliente valioso | G16: Recencia, frecuencia, monto y margen. Los tres requisitos de un segmento útil: accionable, medible y estable.
A17: 16 | B17: 07-oct-2026 | C17: Miércoles | D17: 8 | E17: Corte de medio semestre | F17: Segmentar, nombrar y accionar | G17: qcut y groupby para el puntaje RFM+P. Nombrar los segmentos y escribir el mensaje comercial de cada uno. KMeans con escalador robusto como contraste: la máquina encuentra los segmentos que el grupo definió a mano. | H17: PROYECTO DE MEDIO SEMESTRE: análisis RFM+P con recomendación comercial por segmento. Se entrega durante el receso. DataCamp: Unsupervised Learning in Python. | I17: casos/Caso_01_Segmentacion_Clientes_Retail.md · casos/Entregable_Intermedio_Mitad_Seminario.md
A18: — | B18: 12-oct-2026 | C18: Lunes | D18: — | E18: — | F18: RECESO · Receso académico de medio semestre y Feriado Independencia de Guayaquil
A19: — | B19: 14-oct-2026 | C19: Miércoles | D19: — | E19: — | F19: RECESO · Receso académico de medio semestre y Feriado Independencia de Guayaquil
A20: 17 | B20: 19-oct-2026 | C20: Lunes | D20: 9 | E20: III · Decidir con datos | F20: Comparado con qué | G20: Ruido frente a señal, regresión a la media, variables de confusión y causalidad inversa. Caso: los clientes del programa de fidelidad gastan el doble. | H20: Devolución del proyecto de medio semestre.
A21: 18 | B21: 21-oct-2026 | C21: Miércoles | D21: 9 | E21: III · Decidir con datos | F21: Pruebas estadísticas y diseño experimental | G21: Prueba t, chi cuadrado y ANOVA sobre la base del proyecto. Diseño de una prueba A y B ejecutable, con unidad de asignación, duración y presupuesto. | H21: Deber 5: diseño experimental de una página. | I21: S07-C2 · Hipótesis y pruebas estadísticas · clase_14.ipynb
A22: 19 | B22: 26-oct-2026 | C22: Lunes | D22: 10 | E22: III · Decidir con datos | F22: De la eficiencia al modelo de negocio | G22: Qué es transformación digital y qué es solamente comprar software. Madurez digital y dónde se rompe la experiencia del cliente.
A23: 20 | B23: 28-oct-2026 | C23: Miércoles | D23: 10 | E23: III · Decidir con datos | F23: Customer journey map y service blueprint | G23: Mapa del proceso del negocio del proyecto. Sobre el blueprint se marca dónde nace cada dato y qué decisión se toma hoy a ciegas. | H23: Journey map y blueprint anotados con los puntos de captura de datos.
A24: — | B24: 02-nov-2026 | C24: Lunes | D24: — | E24: — | F24: FERIADO · Feriado Día de Difuntos e Independencia de Cuenca
A25: 21 | B25: 04-nov-2026 | C25: Miércoles | D25: 11 | E25: III · Decidir con datos | F25: Semana comprimida · El mapa de los modelos y la ecuación de valor | G25: Sesión única de 90 minutos por el feriado del lunes. Treinta minutos de concepto: pronóstico, propensión, segmentación, asociación y optimización, qué decisión habilita cada familia y por qué la línea base es obligatoria. Sesenta minutos de taller: catálogo de doce problemas de negocio, cada grupo asigna familia, decisión, línea base y valor anual estimado, y se descubre cuáles no justifican ningún modelo. | H25: Evaluación intermedia sobre criterio de negocio. | I25: S06-C2 · Métricas · clase_12.ipynb (sección 2) · simuladores/simulador-train-test.html
A26: 22 | B26: 09-nov-2026 | C26: Lunes | D26: 12 | E26: IV · Predecir | F26: Una variable explica otra | G26: Mínimos cuadrados, lectura del coeficiente en unidades del negocio y error de pronóstico asimétrico: quedarse sin producto y que sobre producto no cuestan lo mismo.
A27: 23 | B27: 11-nov-2026 | C27: Miércoles | D27: 12 | E27: IV · Predecir | F27: Pronóstico con línea base | G27: LinearRegression y DummyRegressor sobre los datos del proyecto. Primero la regla ingenua, luego la regresión, y comparación honesta entre ambas con error porcentual. | H27: Deber 6: pronóstico con línea base declarada. DataCamp: Introduction to Regression with statsmodels. | I27: S05-C1 · Regresiones · clase_09.ipynb (secciones 1-2) · simuladores/simulador-regresion-lineal.html · simuladores/simulador-regresion-3D-advertising.html
A28: 24 | B28: 16-nov-2026 | C28: Lunes | D28: 13 | E28: IV · Predecir | F28: Varias variables a la vez | G28: Variables categóricas, multicolinealidad y el factor VIF. Cuándo la curva es razonable y cuándo es trampa. Diagnóstico de residuos y los cuatro supuestos del OLS.
A29: 25 | B29: 18-nov-2026 | C29: Miércoles | D29: 13 | E29: IV · Predecir | F29: Modelo múltiple del negocio | G29: Ajuste, revisión de supuestos y presentación del resultado en una frase que un gerente pueda accionar. | H29: Avance de proyecto: modelo de pronóstico documentado. | I29: S05-C1 · Regresiones · clase_09.ipynb (secciones 3-6 y 8) · simuladores/simulador-vif.html · simuladores/simulador-overfitting.html · casos/Caso_03_Scouting_FIFA.md
A30: 26 | B30: 23-nov-2026 | C30: Lunes | D30: 14 | E30: IV · Predecir | F30: Probabilidad como recurso de focalización | G30: Matriz de confusión traducida a dinero. El umbral como palanca gerencial. Clases desbalanceadas y por qué la exactitud engaña.
A31: 27 | B31: 25-nov-2026 | C31: Miércoles | D31: 14 | E31: IV · Predecir | F31: Focalización con presupuesto limitado | G31: LogisticRegression y DecisionTreeClassifier. Si solo alcanza para el veinte por ciento de la cartera, a quiénes y por qué. | H31: Deber 7: recomendación de focalización con retorno esperado. DataCamp: Supervised Learning with scikit-learn. | I31: S05-C2 · Regresión Logística · clase_10.ipynb · S06-C1 · Árbol de Decisión · clase_11.ipynb · S06-C2 · Métricas · clase_12.ipynb · simuladores/simulador-confusion-matrix.html · casos/Caso_08_Fraude_Tarjetas.md
A32: 28 | B32: 30-nov-2026 | C32: Lunes | D32: 15 | E32: V · Responder por el modelo | F32: Un modelo aprende del pasado y reproduce sus desigualdades | G32: Sesgo, privacidad y decisiones automatizadas sobre personas. Caso de riesgo crediticio. Qué se le puede explicar a quien recibe un no.
A33: 29 | B33: 02-dic-2026 | C33: Miércoles | D33: 15 | E33: V · Responder por el modelo | F33: Consultoría entre grupos | G33: Ataque a supuestos ajenos, auditoría del modelo propio y ensayo de la defensa. | H33: Borrador completo del cuaderno reproducible.
A34: 30 | B34: 07-dic-2026 | C34: Lunes | D34: 16 | E34: V · Responder por el modelo | F34: Presentaciones finales · primera mitad | G34: Diez minutos de exposición y diez de preguntas ante panel. Evaluación docente abierta. | H34: Proyecto final: recomendación de una página y cuaderno reproducible.
A35: 31 | B35: 09-dic-2026 | C35: Miércoles | D35: 16 | E35: V · Responder por el modelo | F35: Presentaciones finales · segunda mitad y cierre | G35: Última sesión del semestre. Cierre del curso y evaluación 360 entre pares. | H35: Evaluación 360. Cierra la evaluación docente el 10-dic-2026. | I35: SF · Presentaciones finales · clase_17.ipynb

Sheet Entregas y certificaciones
A1: Fecha | B1: Día | C1: Semana | D1: Tema de la semana | E1: Entregable
A2: 17-ago-2026 | B2: Lunes | C2: 1 | D2: Introducción a Business Analytics y Big Data en la era de la IA | E2: Presentación del curso y del proyecto integrador. Firma del contrato de grupo.
A3: 19-ago-2026 | B3: Miércoles | C3: 1 | D3: Introducción a Business Analytics y Big Data en la era de la IA | E3: Contrato de grupo firmado. DataCamp: Understanding Data Science.
A4: 26-ago-2026 | B4: Miércoles | C4: 2 | D4: Business Analytics en las organizaciones. La pregunta antes del dato | E4: Deber 1: ficha de análisis de una página, sin código.
A5: 02-sep-2026 | B5: Miércoles | C5: 3 | D5: Estadística descriptiva aplicada al negocio | E5: DataCamp: Introduction to Python.
A6: 09-sep-2026 | B6: Miércoles | C6: 4 | D6: Anatomía y calidad de los datos | E6: Deber 2: bitácora de limpieza. Propuesta de proyecto final.
A7: 16-sep-2026 | B7: Miércoles | C7: 5 | D7: Manipulación de datos. Agrupar, limpiar y combinar | E7: Deber 3: tabla de indicadores reproducible. DataCamp: Data Manipulation with pandas y Joining Data with pandas.
A8: 21-sep-2026 | B8: Lunes | C8: 6 | D8: Visualización de datos | E8: Lectura previa: Storytelling con datos (Knaflic).
A9: 23-sep-2026 | B9: Miércoles | C9: 6 | D9: Visualización de datos | E9: Deber 4: tres gráficos anotados del negocio. DataCamp: Introduction to Data Visualization with Matplotlib.
A10: 30-sep-2026 | B10: Miércoles | C10: 7 | D10: Visualización avanzada y tableros | E10: Tablero interactivo entregado dentro del cuaderno.
A11: 07-oct-2026 | B11: Miércoles | C11: 8 | D11: ¿Quiénes son mis clientes y cuánto valen? | E11: PROYECTO DE MEDIO SEMESTRE: análisis RFM+P con recomendación comercial por segmento. Se entrega durante el receso. DataCamp: Unsupervised Learning in Python.
A12: 19-oct-2026 | B12: Lunes | C12: 9 | D12: Comparación, variabilidad y causalidad | E12: Devolución del proyecto de medio semestre.
A13: 21-oct-2026 | B13: Miércoles | C13: 9 | D13: Comparación, variabilidad y causalidad | E13: Deber 5: diseño experimental de una página.
... A21: 09-dic-2026 | B21: Miércoles | C21: 16 | D21: Cierre del curso y presentación final | E21: Evaluación 360. Cierra la evaluación docente el 10-dic-2026.

Sheet Pendientes de construir
A1: Fecha límite | B1: Semana | C1: Qué falta | D1: Situación
A2: 26-oct-2026 | B2: 10 · Estrategia, transformación digital y experiencia del cliente | C2: Sesión conceptual del lunes sobre transformación digital y modelo de negocio | D2: No existe en ninguno de los cursos anteriores ni en el seminario de Python
A3: 04-nov-2026 | B3: 11 · Modelos analíticos. Tipos de modelos y creación de valor | C3: Catálogo de doce problemas de negocio y guion de la sesión comprimida de 90 min | D3: El caso Harvard de Blue Detergent es el único insumo
A4: 30-nov-2026 | B4: 15 · De la predicción a la decisión. Ética y gobernanza | C4: La semana entera: caso de riesgo crediticio y clínica de consultoría entre grupos | D4: Ninguno de los diez casos del seminario menciona sesgo, equidad ni privacidad
A5: 14-sep-2026 | B5: 5 · Manipulación de datos. Agrupar, limpiar y combinar | C5: Las uniones: merge, concat y cardinalidad | D5: El cuaderno de Pandas II del seminario las promete en su plan pero no las implementa
A6: 07-oct-2026 | B6: 8 · ¿Quiénes son mis clientes y cuánto valen? | C6: Decidir dataset del proyecto de medio semestre | D6: El Caso 01 es RFM sin margen y corre sobre Online Retail II; el cuaderno de 202410 usa SuperStore y sí trae Profit

Sheet Índice
B2: ÍNDICE · Guía del Profesor · Calendario Académico USFQ Galápagos 2026-2027
B3: Haz clic en cualquier nombre para ir a la hoja correspondiente.
B5: Hoja | C5: Desde | D5: Hasta | E5: Sesiones | F5: Modalidad / contenido
B6: Instrucciones | F6: Legenda, reglas de carga horaria y supuestos
B7: Feriados y Recesos | F7: Los 12 feriados y recesos académicos del año
B8: Resumen Periodos | F8: Fechas de todos los periodos y módulos
B10: MATERIAS DE SEMESTRE COMPLETO · 1.5 h por sesión
B11: S1 Lun-Mié | C11: 17-ago-2026 | D11: 11-dic-2026 | E11: =COUNTIF('S1 Lun-Mié'!F12:F400,"Clase") -> 31 | F11: Lun y Mié · 1.5 h
B12: S1 Mar-Jue | C12: 17-ago-2026 | D12: 11-dic-2026 | E12: =COUNTIF('S1 Mar-Jue'!F12:F400,"Clase") -> 31 | F12: Mar y Jue · 1.5 h
B13: S2 Lun-Mié | C13: 11-ene-2027 | D13: 07-may-2027 | E13: =COUNTIF('S2 Lun-Mié'!F12:F400,"Clase") -> 31 | F13: Lun y Mié · 1.5 h
B14: S2 Mar-Jue | C14: 11-ene-2027 | D14: 07-may-2027 | E14: =COUNTIF('S2 Mar-Jue'!F12:F400,"Clase") -> 30 | F14: Mar y Jue · 1.5 h
B16: PRIMER SEMESTRE 2026-2027 · módulos
B17: S1-Módulo 1 | C17: 17-ago-2026 | D17: 11-sep-2026 | E17: =COUNTIF('S1-Módulo 1'!F12:F400,"Clase") -> 16 | F17: Lun a Jue · 3 h
B18: S1-Módulo 2 | C18: 14-sep-2026 | D18: 09-oct-2026 | E18: =COUNTIF('S1-Módulo 2'!F12:F400,"Clase") -> 16 | F18: Lun a Jue · 3 h
B19: S1-Módulo 3 | C19: 19-oct-2026 | D19: 13-nov-2026 | E19: =COUNTIF('S1-Módulo 3'!F12:F400,"Clase") -> 14 | F19: Lun a Jue · 3 h
B20: S1-Módulo 4 | C20: 16-nov-2026 | D20: 11-dic-2026 | E20: =COUNTIF('S1-Módulo 4'!F12:F400,"Clase") -> 16 | F20: Lun a Jue · 3 h
B21: S1-Módulo A | C21: 17-ago-2026 | D21: 11-oct-2026 | E21: =COUNTIF('S1-Módulo A'!F12:F400,"Clase") -> 32 | F21: En línea / inglés · 1.5 h
B22: S1-Módulo B | C22: 19-oct-2026 | D22: 13-dic-2026 | E22: =COUNTIF('S1-Módulo B'!F12:F400,"Clase") -> 30 | F22: En línea / inglés · 1.5 h
B24: SEGUNDO SEMESTRE 2026-2027 · módulos
B25: S2-Módulo 1 | C25: 11-ene-2027 | D25: 05-feb-2027 | E25: =COUNTIF('S2-Módulo 1'!F12:F400,"Clase") -> 16 | F25: Lun a Jue · 3 h
B26: S2-Módulo 2 | C26: 08-feb-2027 | D26: 05-mar-2027 | E26: =COUNTIF('S2-Módulo 2'!F12:F400,"Clase") -> 13 | F26: Lun a Jue · 3 h
B27: S2-Módulo 3 | C27: 15-mar-2027 | D27: 09-abr-2027 | E27: =COUNTIF('S2-Módulo 3'!F12:F400,"Clase") -> 16 | F27: Lun a Jue · 3 h
B28: S2-Módulo 4 | C28: 12-abr-2027 | D28: 07-may-2027 | E28: =COUNTIF('S2-Módulo 4'!F12:F400,"Clase") -> 16 | F28: Lun a Jue · 3 h
B29: S2-Módulo C | C29: 11-ene-2027 | D29: 07-mar-2027 | E29: =COUNTIF('S2-Módulo C'!F12:F400,"Clase") -> 29 | F29: En línea / inglés · 1.5 h
B30: S2-Módulo D | C30: 15-mar-2027 | D30: 09-may-2027 | E30: =COUNTIF('S2-Módulo D'!F12:F400,"Clase") -> 32 | F30: En línea / inglés · 1.5 h
B32: VERANO 2026-2027 · módulos
B33: V-Módulo 1 | C33: 10-may-2027 | D33: 04-jun-2027 | E33: =COUNTIF('V-Módulo 1'!F12:F400,"Clase") -> 15 | F33: Lun a Jue · 3 h
B34: V-Módulo 2 | C34: 07-jun-2027 | D34: 02-jul-2027 | E34: =COUNTIF('V-Módulo 2'!F12:F400,"Clase") -> 16 | F34: Lun a Jue · 3 h
B35: V-Módulo 3 | C35: 05-jul-2027 | D35: 30-jul-2027 | E35: =COUNTIF('V-Módulo 3'!F12:F400,"Clase") -> 16 | F35: Lun a Jue · 3 h
B36: V-En línea | C36: 25-may-2027 | D36: 25-jul-2027 | E36: =COUNTIF('V-En línea'!F12:F400,"Clase") -> 32 | F36: En línea / inglés · 1.5 h
B37: V-Inglés E | C37: 10-may-2027 | D37: 25-jun-2027 | E37: =COUNTIF('V-Inglés E'!F12:F400,"Clase") -> 27 | F37: En línea / inglés · 1.5 h
B38: V-Inglés F | C38: 28-jun-2027 | D38: 13-ago-2027 | E38: =COUNTIF('V-Inglés F'!F12:F400,"Clase") -> 27 | F38: En línea / inglés · 1.5 h

Sheet Instrucciones
B2: GUÍA DEL PROFESOR · Calendario Académico USFQ Galápagos 2026-2027
B3: Fuente: Calendario Académico Galápagos 2026-2027 (hojas 'Calendario WEB 2026-2027' y 'Partes de Periodo 2026-2027').
B5: ESTRUCTURA DEL LIBRO
B6: Columnas Tema y Entregas | C6: Quedan en blanco para que cada profesor las complete y las traslade directamente al syllabus.
B7: Columna Semana | C7: Número de semana de clase dentro del módulo o del semestre.
B8: Feriados y Recesos | C8: Los 12 feriados y recesos académicos del año, con indicación de cuáles no aplican a modalidad en línea.
B9: Resumen Periodos | C9: Fechas de inicio y fin de cada periodo y módulo.
B10: S1 / S2 · Lun-Mié y Mar-Jue | C10: Materias de semestre completo: 2 sesiones semanales de 1.5 h.
B11: S1-Módulo 1..4 · S2-Módulo 1..4 · V-Módulo 1..3 | C11: Materias modulares de un mes: lunes a jueves, 3 h diarias. No hay clases los viernes.
B12: S1-Módulo A/B · S2-Módulo C/D · V-En línea · V-Inglés E/F | C12: Módulos de 7 y 8 semanas (en línea y niveles de inglés).
B14: SIGNIFICADO DE LA COLUMNA 'ESTADO'
B15: Asincrónico | C15: Sesión de trabajo autónomo, sin clase presencial.
B16: Clase | C16: Sesión presencial regular. La última del módulo aparece resaltada en verde.
B17: FERIADO | C17: Día de feriado nacional o local: no hay clase.
B18: RECESO | C18: Receso académico: no hay clase. No aplica a materias de modalidad en línea.
B19: Fondo amarillo | C19: Días en que está abierta la evaluación docente por parte de los estudiantes. La ventana cierra antes del último día de clase.
B21: Sin clases los viernes | C21: Todas las materias funcionan de lunes a jueves.
B23: SUPUESTOS
B24: Sin horarios | C24: Este libro es una guía de calendario por módulo: no contiene horas de inicio ni de fin. El horario real lo asigna la coordinación.
B25: Recesos y modalidad en línea | C25: Los recesos académicos no aplican a materias en línea (nota del calendario oficial); en esas hojas los días de receso se mantienen como clase.

Sheet Feriados y Recesos
B2: FERIADOS Y RECESOS ACADÉMICOS 2026-2027
B4: Actividad | C4: Desde | D4: Hasta | E4: Tipo | F4: Días | G4: Aplica a modalidad en línea
B5: Feriado Primer Grito de Independencia | C5: 08-ago-2026 | D5: 10-ago-2026 | E5: Feriado | F5: 3 | G5: Sí
B6: Receso académico de medio semestre y Feriado Independencia de Guayaquil | C6: 09-oct-2026 | D6: 18-oct-2026 | E6: Receso | F6: 10 | G6: No
B7: Feriado Día de Difuntos e Independencia de Cuenca | C7: 31-oct-2026 | D7: 03-nov-2026 | E7: Feriado | F7: 4 | G7: Sí
B8: Receso académico de Navidad y Año Nuevo (estudiantes) | C8: 12-dic-2026 | D8: 10-ene-2027 | E8: Receso | F8: 30 | G8: No
B9: Vacaciones personal académico y administrativo | C9: 19-dic-2026 | D9: 03-ene-2027 | E9: Receso | F9: 16 | G9: No
B10: Feriado Carnaval | C10: 06-feb-2027 | D10: 09-feb-2027 | E10: Feriado | F10: 4 | G10: Sí
B11: Feriado Provincialización de Galápagos | C11: 18-feb-2027 | D11: 18-feb-2027 | E11: Feriado | F11: 1 | G11: Sí
B12: Receso académico de medio semestre | C12: 08-mar-2027 | D12: 14-mar-2027 | E12: Receso | F12: 7 | G12: No
B13: Feriado Viernes Santo | C13: 26-mar-2027 | D13: 28-mar-2027 | E13: Feriado | F13: 3 | G13: Sí
B14: Feriado Día del Trabajo | C14: 30-abr-2027 | D14: 02-may-2027 | E14: Feriado | F14: 3 | G14: Sí
B15: Feriado Batalla del Pichincha | C15: 22-may-2027 | D15: 24-may-2027 | E15: Feriado | F15: 3 | G15: Sí
B16: Feriado Primer Grito de Independencia | C16: 07-ago-2027 | D16: 09-ago-2027 | E16: Feriado | F16: 3 | G16: Sí
B18: Nota: los recesos académicos no aplican para materias de modalidad en línea.

Sheet Resumen Periodos
B2: RESUMEN DE PERIODOS Y MÓDULOS 2026-2027
B4: Periodo / Módulo | C4: Desde | D4: Hasta | E4: Semanas | F4: Modalidad | G4: Días de clase | H4: Horas por sesión
B5: Primer Semestre Galápagos 2026-2027 · materias de semestre completo | C5: 17-ago-2026 | D5: 11-dic-2026 | E5: 18 | F5: Presencial / Semipresencial | G5: Lun-Mié o Mar-Jue | H5: 1.5
B6: Segundo Semestre Galápagos 2026-2027 · materias de semestre completo | C6: 11-ene-2027 | D6: 07-may-2027 | E6: 18 | F6: Presencial / Semipresencial | G6: Lun-Mié o Mar-Jue | H6: 1.5
B7: S1 · Módulo 1 (presencial / semipresencial) | C7: 17-ago-2026 | D7: 11-sep-2026 | E7: 4 | F7: Presencial / Semipresencial | G7: Lunes a jueves | H7: 3.0
B8: S1 · Módulo 2 (presencial / semipresencial) | C8: 14-sep-2026 | D8: 09-oct-2026 | E8: 4 | F8: Presencial / Semipresencial | G8: Lunes a jueves | H8: 3.0
B9: S1 · Módulo 3 (presencial / semipresencial) | C9: 19-oct-2026 | D9: 13-nov-2026 | E9: 4 | F9: Presencial / Semipresencial | G9: Lunes a jueves | H9: 3.0
B10: S1 · Módulo 4 (presencial / semipresencial) | C10: 16-nov-2026 | D10: 11-dic-2026 | E10: 4 | F10: Presencial / Semipresencial | G10: Lunes a jueves | H10: 3.0
B11: S1 · Módulo A (en línea / niveles de inglés · 8 semanas) | C11: 17-ago-2026 | D11: 11-oct-2026 | E11: 8 | F11: En línea / Inglés | G11: Lun a jue · según modalidad | H11: 1.5
B12: S1 · Módulo B (en línea / niveles de inglés · 8 semanas) | C12: 19-oct-2026 | D12: 13-dic-2026 | E12: 8 | F12: En línea / Inglés | G12: Lun a jue · según modalidad | H12: 1.5
B13: S2 · Módulo 1 (presencial / semipresencial) | C13: 11-ene-2027 | D13: 05-feb-2027 | E13: 4 | F13: Presencial / Semipresencial | G13: Lunes a jueves | H13: 3.0
B14: S2 · Módulo 2 (presencial / semipresencial) | C14: 08-feb-2027 | D14: 05-mar-2027 | E14: 4 | F14: Presencial / Semipresencial | G14: Lunes a jueves | H14: 3.0
B15: S2 · Módulo 3 (presencial / semipresencial) | C15: 15-mar-2027 | D15: 09-abr-2027 | E15: 4 | F15: Presencial / Semipresencial | G15: Lunes a jueves | H15: 3.0
B16: S2 · Módulo 4 (presencial / semipresencial) | C16: 12-abr-2027 | D16: 07-may-2027 | E16: 4 | F16: Presencial / Semipresencial | G16: Lunes a jueves | H16: 3.0
... B24: Verano · Niveles de inglés Módulo F (7 semanas) | C24: 28-jun-2027 | D24: 13-ago-2027 | E24: 7 | F24: Presencial (inglés) | G24: Lun a jue · según modalidad | H24: 1.5

Sheet S1 Mar-Jue
B1: ← Volver al índice
B2: Primer Semestre Galápagos 2026-2027 · Materias de semestre completo (Mar-Jue) | K2: RESUMEN DEL MÓDULO
B3: Materias de semestre completo · dos sesiones semanales de 1.5 h · 17-ago-2026 al 11-dic-2026. | K3: Sesiones de clase | L3: =COUNTIF(F12:F45,"Clase") -> 31
B4: Evaluación docente por parte de estudiantes (202610-G4 (fin de semestre)): del 07-dic-2026 al 10-dic-2026 — cierra antes del último día de clase. | K4: Sesiones asincrónicas | L4: =COUNTIF(F12:F45,"Asincrónico") -> 0
K5: Días sin clase (feriado / receso) | L5: =COUNTIF(F12:F45,"FERIADO")+COUNTIF(F12:F45,"RECESO") -> 3
K6: Semanas | L6: =MAX(B12:B45) -> 17
K7: Evaluación docente | L7: ="07-dic-2026 al 10-dic-2026" -> 07-dic-2026 al 10-dic-2026
B11: Semana | C11: N° Sesión | D11: Fecha | E11: Día | F11: Estado | G11: Tema | H11: Entregas | I11: Observación
B12: 1 | C12: =IF(OR(F12="FERIADO",F12="RECESO"),"—",ROWS($F$12:F12)-COUNTIF($F$12:F12,"FERIADO")-COUNTIF($F$12:F12,"RECESO")) -> 1 | D12: 18-ago-2026 | E12: Martes | F12: Clase
B13: 1 | C13: =IF(OR(F13="FERIADO",F13="RECESO"),"—",ROWS($F$12:F13)-COUNTIF($F$12:F13,"FERIADO")-COUNTIF($F$12:F13,"RECESO")) -> 2 | D13: 20-ago-2026 | E13: Jueves | F13: Clase
B14: 2 | C14: =IF(OR(F14="FERIADO",F14="RECESO"),"—",ROWS($F$12:F14)-COUNTIF($F$12:F14,"FERIADO")-COUNTIF($F$12:F14,"RECESO")) -> 3 | D14: 25-ago-2026 | E14: Martes | F14: Clase
B15: 2 | C15: =IF(OR(F15="FERIADO",F15="RECESO"),"—",ROWS($F$12:F15)-COUNTIF($F$12:F15,"FERIADO")-COUNTIF($F$12:F15,"RECESO")) -> 4 | D15: 27-ago-2026 | E15: Jueves | F15: Clase
B16: 3 | C16: =IF(OR(F16="FERIADO",F16="RECESO"),"—",ROWS($F$12:F16)-COUNTIF($F$12:F16,"FERIADO")-COUNTIF($F$12:F16,"RECESO")) -> 5 | D16: 01-sep-2026 | E16: Martes | F16: Clase
B17: 3 | C17: =IF(OR(F17="FERIADO",F17="RECESO"),"—",ROWS($F$12:F17)-COUNTIF($F$12:F17,"FERIADO")-COUNTIF($F$12:F17,"RECESO")) -> 6 | D17: 03-sep-2026 | E17: Jueves | F17: Clase
B18: 4 | C18: =IF(OR(F18="FERIADO",F18="RECESO"),"—",ROWS($F$12:F18)-COUNTIF($F$12:F18,"FERIADO")-COUNTIF($F$12:F18,"RECESO")) -> 7 | D18: 08-sep-2026 | E18: Martes | F18: Clase
B19: 4 | C19: =IF(OR(F19="FERIADO",F19="RECESO"),"—",ROWS($F$12:F19)-COUNTIF($F$12:F19,"FERIADO")-COUNTIF($F$12:F19,"RECESO")) -> 8 | D19: 10-sep-2026 | E19: Jueves | F19: Clase
B20: 5 | C20: =IF(OR(F20="FERIADO",F20="RECESO"),"—",ROWS($F$12:F20)-COUNTIF($F$12:F20,"FERIADO")-COUNTIF($F$12:F20,"RECESO")) -> 9 | D20: 15-sep-2026 | E20: Martes | F20: Clase
B21: 5 | C21: =IF(OR(F21="FERIADO",F21="RECESO"),"—",ROWS($F$12:F21)-COUNTIF($F$12:F21,"FERIADO")-COUNTIF($F$12:F21,"RECESO")) -> 10 | D21: 17-sep-2026 | E21: Jueves | F21: Clase
B22: 6 | C22: =IF(OR(F22="FERIADO",F22="RECESO"),"—",ROWS($F$12:F22)-COUNTIF($F$12:F22,"FERIADO")-COUNTIF($F$12:F22,"RECESO")) -> 11 | D22: 22-sep-2026 | E22: Martes | F22: Clase
B23: 6 | C23: =IF(OR(F23="FERIADO",F23="RECESO"),"—",ROWS($F$12:F23)-COUNTIF($F$12:F23,"FERIADO")-COUNTIF($F$12:F23,"RECESO")) -> 12 | D23: 24-sep-2026 | E23: Jueves | F23: Clase
... B27: 8 | C27: =IF(OR(F27="FERIADO",F27="RECESO"),"—",ROWS($F$12:F27)-COUNTIF($F$12:F27,"FERIADO")-COUNTIF($F$12:F27,"RECESO")) -> 16 | D27: 08-oct-2026 | E27: Jueves | F27: Clase
B28: 9 | C28: =IF(OR(F28="FERIADO",F28="RECESO"),"—",ROWS($F$12:F28)-COUNTIF($F$12:F28,"FERIADO")-COUNTIF($F$12:F28,"RECESO")) -> — | D28: 13-oct-2026 | E28: Martes | F28: RECESO | I28: Receso académico de medio semestre y Feriado Independencia de Guayaquil
B29: 9 | C29: =IF(OR(F29="FERIADO",F29="RECESO"),"—",ROWS($F$12:F29)-COUNTIF($F$12:F29,"FERIADO")-COUNTIF($F$12:F29,"RECESO")) -> — | D29: 15-oct-2026 | E29: Jueves | F29: RECESO | I29: Receso académico de medio semestre y Feriado Independencia de Guayaquil
B30: 10 | C30: =IF(OR(F30="FERIADO",F30="RECESO"),"—",ROWS($F$12:F30)-COUNTIF($F$12:F30,"FERIADO")-COUNTIF($F$12:F30,"RECESO")) -> 17 | D30: 20-oct-2026 | E30: Martes | F30: Clase
B31: 10 | C31: =IF(OR(F31="FERIADO",F31="RECESO"),"—",ROWS($F$12:F31)-COUNTIF($F$12:F31,"FERIADO")-COUNTIF($F$12:F31,"RECESO")) -> 18 | D31: 22-oct-2026 | E31: Jueves | F31: Clase
B32: 11 | C32: =IF(OR(F32="FERIADO",F32="RECESO"),"—",ROWS($F$12:F32)-COUNTIF($F$12:F32,"FERIADO")-COUNTIF($F$12:F32,"RECESO")) -> 19 | D32: 27-oct-2026 | E32: Martes | F32: Clase
B33: 11 | C33: =IF(OR(F33="FERIADO",F33="RECESO"),"—",ROWS($F$12:F33)-COUNTIF($F$12:F33,"FERIADO")-COUNTIF($F$12:F33,"RECESO")) -> 20 | D33: 29-oct-2026 | E33: Jueves | F33: Clase
B34: 12 | C34: =IF(OR(F34="FERIADO",F34="RECESO"),"—",ROWS($F$12:F34)-COUNTIF($F$12:F34,"FERIADO")-COUNTIF($F$12:F34,"RECESO")) -> — | D34: 03-nov-2026 | E34: Martes | F34: FERIADO | I34: Feriado Día de Difuntos e Independencia de Cuenca
B35: 12 | C35: =IF(OR(F35="FERIADO",F35="RECESO"),"—",ROWS($F$12:F35)-COUNTIF($F$12:F35,"FERIADO")-COUNTIF($F$12:F35,"RECESO")) -> 21 | D35: 05-nov-2026 | E35: Jueves | F35: Clase
B36: 13 | C36: =IF(OR(F36="FERIADO",F36="RECESO"),"—",ROWS($F$12:F36)-COUNTIF($F$12:F36,"FERIADO")-COUNTIF($F$12:F36,"RECESO")) -> 22 | D36: 10-nov-2026 | E36: Martes | F36: Clase
B37: 13 | C37: =IF(OR(F37="FERIADO",F37="RECESO"),"—",ROWS($F$12:F37)-COUNTIF($F$12:F37,"FERIADO")-COUNTIF($F$12:F37,"RECESO")) -> 23 | D37: 12-nov-2026 | E37: Jueves | F37: Clase
B38: 14 | C38: =IF(OR(F38="FERIADO",F38="RECESO"),"—",ROWS($F$12:F38)-COUNTIF($F$12:F38,"FERIADO")-COUNTIF($F$12:F38,"RECESO")) -> 24 | D38: 17-nov-2026 | E38: Martes | F38: Clase
B39: 14 | C39: =IF(OR(F39="FERIADO",F39="RECESO"),"—",ROWS($F$12:F39)-COUNTIF($F$12:F39,"FERIADO")-COUNTIF($F$12:F39,"RECESO")) -> 25 | D39: 19-nov-2026 | E39: Jueves | F39: Clase
B40: 15 | C40: =IF(OR(F40="FERIADO",F40="RECESO"),"—",ROWS($F$12:F40)-COUNTIF($F$12:F40,"FERIADO")-COUNTIF($F$12:F40,"RECESO")) -> 26 | D40: 24-nov-2026 | E40: Martes | F40: Clase
B41: 15 | C41: =IF(OR(F41="FERIADO",F41="RECESO"),"—",ROWS($F$12:F41)-COUNTIF($F$12:F41,"FERIADO")-COUNTIF($F$12:F41,"RECESO")) -> 27 | D41: 26-nov-2026 | E41: Jueves | F41: Clase
B42: 16 | C42: =IF(OR(F42="FERIADO",F42="RECESO"),"—",ROWS($F$12:F42)-COUNTIF($F$12:F42,"FERIADO")-COUNTIF($F$12:F42,"RECESO")) -> 28 | D42: 01-dic-2026 | E42: Martes | F42: Clase
B43: 16 | C43: =IF(OR(F43="FERIADO",F43="RECESO"),"—",ROWS($F$12:F43)-COUNTIF($F$12:F43,"FERIADO")-COUNTIF($F$12:F43,"RECESO")) -> 29 | D43: 03-dic-2026 | E43: Jueves | F43: Clase
B44: 17 | C44: =IF(OR(F44="FERIADO",F44="RECESO"),"—",ROWS($F$12:F44)-COUNTIF($F$12:F44,"FERIADO")-COUNTIF($F$12:F44,"RECESO")) -> 30 | D44: 08-dic-2026 | E44: Martes | F44: Clase | I44: Evaluación docente ABIERTA (cierra 10-dic-2026)
B45: 17 | C45: =IF(OR(F45="FERIADO",F45="RECESO"),"—",ROWS($F$12:F45)-COUNTIF($F$12:F45,"FERIADO")-COUNTIF($F$12:F45,"RECESO")) -> 31 | D45: 10-dic-2026 | E45: Jueves | F45: Clase | I45: Última sesión del módulo · Evaluación docente ABIERTA (cierra 10-dic-2026)

Sheet S2 Lun-Mié
B1: ← Volver al índice
B2: Segundo Semestre Galápagos 2026-2027 · Materias de semestre completo (Lun-Mié) | K2: RESUMEN DEL MÓDULO
B3: Materias de semestre completo · dos sesiones semanales de 1.5 h · 11-ene-2027 al 07-may-2027. | K3: Sesiones de clase | L3: =COUNTIF(F12:F45,"Clase") -> 31
B4: Evaluación docente por parte de estudiantes (202620-G4 (fin de semestre)): del 03-may-2027 al 06-may-2027 — cierra antes del último día de clase. | K4: Sesiones asincrónicas | L4: =COUNTIF(F12:F45,"Asincrónico") -> 0
K5: Días sin clase (feriado / receso) | L5: =COUNTIF(F12:F45,"FERIADO")+COUNTIF(F12:F45,"RECESO") -> 3
K6: Semanas | L6: =MAX(B12:B45) -> 17
K7: Evaluación docente | L7: ="03-may-2027 al 06-may-2027" -> 03-may-2027 al 06-may-2027
B11: Semana | C11: N° Sesión | D11: Fecha | E11: Día | F11: Estado | G11: Tema | H11: Entregas | I11: Observación
B12: 1 | C12: =IF(OR(F12="FERIADO",F12="RECESO"),"—",ROWS($F$12:F12)-COUNTIF($F$12:F12,"FERIADO")-COUNTIF($F$12:F12,"RECESO")) -> 1 | D12: 11-ene-2027 | E12: Lunes | F12: Clase
B13: 1 | C13: =IF(OR(F13="FERIADO",F13="RECESO"),"—",ROWS($F$12:F13)-COUNTIF($F$12:F13,"FERIADO")-COUNTIF($F$12:F13,"RECESO")) -> 2 | D13: 13-ene-2027 | E13: Miércoles | F13: Clase
B14: 2 | C14: =IF(OR(F14="FERIADO",F14="RECESO"),"—",ROWS($F$12:F14)-COUNTIF($F$12:F14,"FERIADO")-COUNTIF($F$12:F14,"RECESO")) -> 3 | D14: 18-ene-2027 | E14: Lunes | F14: Clase
B15: 2 | C15: =IF(OR(F15="FERIADO",F15="RECESO"),"—",ROWS($F$12:F15)-COUNTIF($F$12:F15,"FERIADO")-COUNTIF($F$12:F15,"RECESO")) -> 4 | D15: 20-ene-2027 | E15: Miércoles | F15: Clase
B16: 3 | C16: =IF(OR(F16="FERIADO",F16="RECESO"),"—",ROWS($F$12:F16)-COUNTIF($F$12:F16,"FERIADO")-COUNTIF($F$12:F16,"RECESO")) -> 5 | D16: 25-ene-2027 | E16: Lunes | F16: Clase
B17: 3 | C17: =IF(OR(F17="FERIADO",F17="RECESO"),"—",ROWS($F$12:F17)-COUNTIF($F$12:F17,"FERIADO")-COUNTIF($F$12:F17,"RECESO")) -> 6 | D17: 27-ene-2027 | E17: Miércoles | F17: Clase
B18: 4 | C18: =IF(OR(F18="FERIADO",F18="RECESO"),"—",ROWS($F$12:F18)-COUNTIF($F$12:F18,"FERIADO")-COUNTIF($F$12:F18,"RECESO")) -> 7 | D18: 01-feb-2027 | E18: Lunes | F18: Clase
B19: 4 | C19: =IF(OR(F19="FERIADO",F19="RECESO"),"—",ROWS($F$12:F19)-COUNTIF($F$12:F19,"FERIADO")-COUNTIF($F$12:F19,"RECESO")) -> 8 | D19: 03-feb-2027 | E19: Miércoles | F19: Clase
B20: 5 | C20: =IF(OR(F20="FERIADO",F20="RECESO"),"—",ROWS($F$12:F20)-COUNTIF($F$12:F20,"FERIADO")-COUNTIF($F$12:F20,"RECESO")) -> — | D20: 08-feb-2027 | E20: Lunes | F20: FERIADO | I20: Feriado Carnaval
B21: 5 | C21: =IF(OR(F21="FERIADO",F21="RECESO"),"—",ROWS($F$12:F21)-COUNTIF($F$12:F21,"FERIADO")-COUNTIF($F$12:F21,"RECESO")) -> 9 | D21: 10-feb-2027 | E21: Miércoles | F21: Clase
B22: 6 | C22: =IF(OR(F22="FERIADO",F22="RECESO"),"—",ROWS($F$12:F22)-COUNTIF($F$12:F22,"FERIADO")-COUNTIF($F$12:F22,"RECESO")) -> 10 | D22: 15-feb-2027 | E22: Lunes | F22: Clase
B23: 6 | C23: =IF(OR(F23="FERIADO",F23="RECESO"),"—",ROWS($F$12:F23)-COUNTIF($F$12:F23,"FERIADO")-COUNTIF($F$12:F23,"RECESO")) -> 11 | D23: 17-feb-2027 | E23: Miércoles | F23: Clase
B24: 7 | C24: =IF(OR(F24="FERIADO",F24="RECESO"),"—",ROWS($F$12:F24)-COUNTIF($F$12:F24,"FERIADO")-COUNTIF($F$12:F24,"RECESO")) -> 12 | D24: 22-feb-2027 | E24: Lunes | F24: Clase
B25: 7 | C25: =IF(OR(F25="FERIADO",F25="RECESO"),"—",ROWS($F$12:F25)-COUNTIF($F$12:F25,"FERIADO")-COUNTIF($F$12:F25,"RECESO")) -> 13 | D25: 24-feb-2027 | E25: Miércoles | F25: Clase
B26: 8 | C26: =IF(OR(F26="FERIADO",F26="RECESO"),"—",ROWS($F$12:F26)-COUNTIF($F$12:F26,"FERIADO")-COUNTIF($F$12:F26,"RECESO")) -> 14 | D26: 01-mar-2027 | E26: Lunes | F26: Clase
B27: 8 | C27: =IF(OR(F27="FERIADO",F27="RECESO"),"—",ROWS($F$12:F27)-COUNTIF($F$12:F27,"FERIADO")-COUNTIF($F$12:F27,"RECESO")) -> 15 | D27: 03-mar-2027 | E27: Miércoles | F27: Clase
B28: 9 | C28: =IF(OR(F28="FERIADO",F28="RECESO"),"—",ROWS($F$12:F28)-COUNTIF($F$12:F28,"FERIADO")-COUNTIF($F$12:F28,"RECESO")) -> — | D28: 08-mar-2027 | E28: Lunes | F28: RECESO | I28: Receso académico de medio semestre
B29: 9 | C29: =IF(OR(F29="FERIADO",F29="RECESO"),"—",ROWS($F$12:F29)-COUNTIF($F$12:F29,"FERIADO")-COUNTIF($F$12:F29,"RECESO")) -> — | D29: 10-mar-2027 | E29: Miércoles | F29: RECESO | I29: Receso académico de medio semestre
B30: 10 | C30: =IF(OR(F30="FERIADO",F30="RECESO"),"—",ROWS($F$12:F30)-COUNTIF($F$12:F30,"FERIADO")-COUNTIF($F$12:F30,"RECESO")) -> 16 | D30: 15-mar-2027 | E30: Lunes | F30: Clase
B31: 10 | C31: =IF(OR(F31="FERIADO",F31="RECESO"),"—",ROWS($F$12:F31)-COUNTIF($F$12:F31,"FERIADO")-COUNTIF($F$12:F31,"RECESO")) -> 17 | D31: 17-mar-2027 | E31: Miércoles | F31: Clase
B32: 11 | C32: =IF(OR(F32="FERIADO",F32="RECESO"),"—",ROWS($F$12:F32)-COUNTIF($F$12:F32,"FERIADO")-COUNTIF($F$12:F32,"RECESO")) -> 18 | D32: 22-mar-2027 | E32: Lunes | F32: Clase
B33: 11 | C33: =IF(OR(F33="FERIADO",F33="RECESO"),"—",ROWS($F$12:F33)-COUNTIF($F$12:F33,"FERIADO")-COUNTIF($F$12:F33,"RECESO")) -> 19 | D33: 24-mar-2027 | E33: Miércoles | F33: Clase
B34: 12 | C34: =IF(OR(F34="FERIADO",F34="RECESO"),"—",ROWS($F$12:F34)-COUNTIF($F$12:F34,"FERIADO")-COUNTIF($F$12:F34,"RECESO")) -> 20 | D34: 29-mar-2027 | E34: Lunes | F34: Clase
B35: 12 | C35: =IF(OR(F35="FERIADO",F35="RECESO"),"—",ROWS($F$12:F35)-COUNTIF($F$12:F35,"FERIADO")-COUNTIF($F$12:F35,"RECESO")) -> 21 | D35: 31-mar-2027 | E35: Miércoles | F35: Clase
B36: 13 | C36: =IF(OR(F36="FERIADO",F36="RECESO"),"—",ROWS($F$12:F36)-COUNTIF($F$12:F36,"FERIADO")-COUNTIF($F$12:F36,"RECESO")) -> 22 | D36: 05-abr-2027 | E36: Lunes | F36: Clase
B37: 13 | C37: =IF(OR(F37="FERIADO",F37="RECESO"),"—",ROWS($F$12:F37)-COUNTIF($F$12:F37,"FERIADO")-COUNTIF($F$12:F37,"RECESO")) -> 23 | D37: 07-abr-2027 | E37: Miércoles | F37: Clase
B38: 14 | C38: =IF(OR(F38="FERIADO",F38="RECESO"),"—",ROWS($F$12:F38)-COUNTIF($F$12:F38,"FERIADO")-COUNTIF($F$12:F38,"RECESO")) -> 24 | D38: 12-abr-2027 | E38: Lunes | F38: Clase
B39: 14 | C39: =IF(OR(F39="FERIADO",F39="RECESO"),"—",ROWS($F$12:F39)-COUNTIF($F$12:F39,"FERIADO")-COUNTIF($F$12:F39,"RECESO")) -> 25 | D39: 14-abr-2027 | E39: Miércoles | F39: Clase
B40: 15 | C40: =IF(OR(F40="FERIADO",F40="RECESO"),"—",ROWS($F$12:F40)-COUNTIF($F$12:F40,"FERIADO")-COUNTIF($F$12:F40,"RECESO")) -> 26 | D40: 19-abr-2027 | E40: Lunes | F40: Clase
B41: 15 | C41: =IF(OR(F41="FERIADO",F41="RECESO"),"—",ROWS($F$12:F41)-COUNTIF($F$12:F41,"FERIADO")-COUNTIF($F$12:F41,"RECESO")) -> 27 | D41: 21-abr-2027 | E41: Miércoles | F41: Clase
... B43: 16 | C43: =IF(OR(F43="FERIADO",F43="RECESO"),"—",ROWS($F$12:F43)-COUNTIF($F$12:F43,"FERIADO")-COUNTIF($F$12:F43,"RECESO")) -> 29 | D43: 28-abr-2027 | E43: Miércoles | F43: Clase
B44: 17 | C44: =IF(OR(F44="FERIADO",F44="RECESO"),"—",ROWS($F$12:F44)-COUNTIF($F$12:F44,"FERIADO")-COUNTIF($F$12:F44,"RECESO")) -> 30 | D44: 03-may-2027 | E44: Lunes | F44: Clase | I44: Evaluación docente ABIERTA (cierra 06-may-2027)
...

Sheet S2 Mar-Jue
B1: ← Volver al índice
B2: Segundo Semestre Galápagos 2026-2027 · Materias de semestre completo (Mar-Jue) | K2: RESUMEN DEL MÓDULO
B3: Materias de semestre completo · dos sesiones semanales de 1.5 h · 11-ene-2027 al 07-may-2027. | K3: Sesiones de clase | L3: =COUNTIF(F12:F45,"Clase") -> 30
B4: Evaluación docente por parte de estudiantes (202620-G4 (fin de semestre)): del 03-may-2027 al 06-may-2027 — cierra antes del último día de clase. | K4: Sesiones asincrónicas | L4: =COUNTIF(F12:F45,"Asincrónico") -> 0
K5: Días sin clase (feriado / receso) | L5: =COUNTIF(F12:F45,"FERIADO")+COUNTIF(F12:F45,"RECESO") -> 4
K6: Semanas | L6: =MAX(B12:B45) -> 17
K7: Evaluación docente | L7: ="03-may-2027 al 06-may-2027" -> 03-may-2027 al 06-may-2027
B11: Semana | C11: N° Sesión | D11: Fecha | E11: Día | F11: Estado | G11: Tema | H11: Entregas | I11: Observación
B12: 1 | C12: =IF(OR(F12="FERIADO",F12="RECESO"),"—",ROWS($F$12:F12)-COUNTIF($F$12:F12,"FERIADO")-COUNTIF($F$12:F12,"RECESO")) -> 1 | D12: 12-ene-2027 | E12: Martes | F12: Clase
B13: 1 | C13: =IF(OR(F13="FERIADO",F13="RECESO"),"—",ROWS($F$12:F13)-COUNTIF($F$12:F13,"FERIADO")-COUNTIF($F$12:F13,"RECESO")) -> 2 | D13: 14-ene-2027 | E13: Jueves | F13: Clase
B14: 2 | C14: =IF(OR(F14="FERIADO",F14="RECESO"),"—",ROWS($F$12:F14)-COUNTIF($F$12:F14,"FERIADO")-COUNTIF($F$12:F14,"RECESO")) -> 3 | D14: 19-ene-2027 | E14: Martes | F14: Clase
B15: 2 | C15: =IF(OR(F15="FERIADO",F15="RECESO"),"—",ROWS($F$12:F15)-COUNTIF($F$12:F15,"FERIADO")-COUNTIF($F$12:F15,"RECESO")) -> 4 | D15: 21-ene-2027 | E15: Jueves | F15: Clase
B16: 3 | C16: =IF(OR(F16="FERIADO",F16="RECESO"),"—",ROWS($F$12:F16)-COUNTIF($F$12:F16,"FERIADO")-COUNTIF($F$12:F16,"RECESO")) -> 5 | D16: 26-ene-2027 | E16: Martes | F16: Clase
B17: 3 | C17: =IF(OR(F17="FERIADO",F17="RECESO"),"—",ROWS($F$12:F17)-COUNTIF($F$12:F17,"FERIADO")-COUNTIF($F$12:F17,"RECESO")) -> 6 | D17: 28-ene-2027 | E17: Jueves | F17: Clase
B18: 4 | C18: =IF(OR(F18="FERIADO",F18="RECESO"),"—",ROWS($F$12:F18)-COUNTIF($F$12:F18,"FERIADO")-COUNTIF($F$12:F18,"RECESO")) -> 7 | D18: 02-feb-2027 | E18: Martes | F18: Clase
B19: 4 | C19: =IF(OR(F19="FERIADO",F19="RECESO"),"—",ROWS($F$12:F19)-COUNTIF($F$12:F19,"FERIADO")-COUNTIF($F$12:F19,"RECESO")) -> 8 | D19: 04-feb-2027 | E19: Jueves | F19: Clase
B20: 5 | C20: =IF(OR(F20="FERIADO",F20="RECESO"),"—",ROWS($F$12:F20)-COUNTIF($F$12:F20,"FERIADO")-COUNTIF($F$12:F20,"RECESO")) -> — | D20: 09-feb-2027 | E20: Martes | F20: FERIADO | I20: Feriado Carnaval
B21: 5 | C21: =IF(OR(F21="FERIADO",F21="RECESO"),"—",ROWS($F$12:F21)-COUNTIF($F$12:F21,"FERIADO")-COUNTIF($F$12:F21,"RECESO")) -> 9 | D21: 11-feb-2027 | E21: Jueves | F21: Clase
B22: 6 | C22: =IF(OR(F22="FERIADO",F22="RECESO"),"—",ROWS($F$12:F22)-COUNTIF($F$12:F22,"FERIADO")-COUNTIF($F$12:F22,"RECESO")) -> 10 | D22: 16-feb-2027 | E22: Martes | F22: Clase
B23: 6 | C23: =IF(OR(F23="FERIADO",F23="RECESO"),"—",ROWS($F$12:F23)-COUNTIF($F$12:F23,"FERIADO")-COUNTIF($F$12:F23,"RECESO")) -> — | D23: 18-feb-2027 | E23: Jueves | F23: FERIADO | I23: Feriado Provincialización de Galápagos
B24: 7 | C24: =IF(OR(F24="FERIADO",F24="RECESO"),"—",ROWS($F$12:F24)-COUNTIF($F$12:F24,"FERIADO")-COUNTIF($F$12:F24,"RECESO")) -> 11 | D24: 23-feb-2027 | E24: Martes | F24: Clase
B25: 7 | C25: =IF(OR(F25="FERIADO",F25="RECESO"),"—",ROWS($F$12:F25)-COUNTIF($F$12:F25,"FERIADO")-COUNTIF($F$12:F25,"RECESO")) -> 12 | D25: 25-feb-2027 | E25: Jueves | F25: Clase
B26: 8 | C26: =IF(OR(F26="FERIADO",F26="RECESO"),"—",ROWS($F$12:F26)-COUNTIF($F$12:F26,"FERIADO")-COUNTIF($F$12:F26,"RECESO")) -> 13 | D26: 02-mar-2027 | E26: Martes | F26: Clase
B27: 8 | C27: =IF(OR(F27="FERIADO",F27="RECESO"),"—",ROWS($F$12:F27)-COUNTIF($F$12:F27,"FERIADO")-COUNTIF($F$12:F27,"RECESO")) -> 14 | D27: 04-mar-2027 | E27: Jueves | F27: Clase
B28: 9 | C28: =IF(OR(F28="FERIADO",F28="RECESO"),"—",ROWS($F$12:F28)-COUNTIF($F$12:F28,"FERIADO")-COUNTIF($F$12:F28,"RECESO")) -> — | D28: 09-mar-2027 | E28: Martes | F28: RECESO | I28: Receso académico de medio semestre
B29: 9 | C29: =IF(OR(F29="FERIADO",F29="RECESO"),"—",ROWS($F$12:F29)-COUNTIF($F$12:F29,"FERIADO")-COUNTIF($F$12:F29,"RECESO")) -> — | D29: 11-mar-2027 | E29: Jueves | F29: RECESO | I29: Receso académico de medio semestre
B30: 10 | C30: =IF(OR(F30="FERIADO",F30="RECESO"),"—",ROWS($F$12:F30)-COUNTIF($F$12:F30,"FERIADO")-COUNTIF($F$12:F30,"RECESO")) -> 15 | D30: 16-mar-2027 | E30: Martes | F30: Clase
B31: 10 | C31: =IF(OR(F31="FERIADO",F31="RECESO"),"—",ROWS($F$12:F31)-COUNTIF($F$12:F31,"FERIADO")-COUNTIF($F$12:F31,"RECESO")) -> 16 | D31: 18-mar-2027 | E31: Jueves | F31: Clase
B32: 11 | C32: =IF(OR(F32="FERIADO",F32="RECESO"),"—",ROWS($F$12:F32)-COUNTIF($F$12:F32,"FERIADO")-COUNTIF($F$12:F32,"RECESO")) -> 17 | D32: 23-mar-2027 | E32: Martes | F32: Clase
B33: 11 | C33: =IF(OR(F33="FERIADO",F33="RECESO"),"—",ROWS($F$12:F33)-COUNTIF($F$12:F33,"FERIADO")-COUNTIF($F$12:F33,"RECESO")) -> 18 | D33: 25-mar-2027 | E33: Jueves | F33: Clase
B34: 12 | C34: =IF(OR(F34="FERIADO",F34="RECESO"),"—",ROWS($F$12:F34)-COUNTIF($F$12:F34,"FERIADO")-COUNTIF($F$12:F34,"RECESO")) -> 19 | D34: 30-mar-2027 | E34: Martes | F34: Clase
B35: 12 | C35: =IF(OR(F35="FERIADO",F35="RECESO"),"—",ROWS($F$12:F35)-COUNTIF($F$12:F35,"FERIADO")-COUNTIF($F$12:F35,"RECESO")) -> 20 | D35: 01-abr-2027 | E35: Jueves | F35: Clase
B36: 13 | C36: =IF(OR(F36="FERIADO",F36="RECESO"),"—",ROWS($F$12:F36)-COUNTIF($F$12:F36,"FERIADO")-COUNTIF($F$12:F36,"RECESO")) -> 21 | D36: 06-abr-2027 | E36: Martes | F36: Clase
B37: 13 | C37: =IF(OR(F37="FERIADO",F37="RECESO"),"—",ROWS($F$12:F37)-COUNTIF($F$12:F37,"FERIADO")-COUNTIF($F$12:F37,"RECESO")) -> 22 | D37: 08-abr-2027 | E37: Jueves | F37: Clase
B38: 14 | C38: =IF(OR(F38="FERIADO",F38="RECESO"),"—",ROWS($F$12:F38)-COUNTIF($F$12:F38,"FERIADO")-COUNTIF($F$12:F38,"RECESO")) -> 23 | D38: 13-abr-2027 | E38: Martes | F38: Clase
B39: 14 | C39: =IF(OR(F39="FERIADO",F39="RECESO"),"—",ROWS($F$12:F39)-COUNTIF($F$12:F39,"FERIADO")-COUNTIF($F$12:F39,"RECESO")) -> 24 | D39: 15-abr-2027 | E39: Jueves | F39: Clase
B40: 15 | C40: =IF(OR(F40="FERIADO",F40="RECESO"),"—",ROWS($F$12:F40)-COUNTIF($F$12:F40,"FERIADO")-COUNTIF($F$12:F40,"RECESO")) -> 25 | D40: 20-abr-2027 | E40: Martes | F40: Clase
B41: 15 | C41: =IF(OR(F41="FERIADO",F41="RECESO"),"—",ROWS($F$12:F41)-COUNTIF($F$12:F41,"FERIADO")-COUNTIF($F$12:F41,"RECESO")) -> 26 | D41: 22-abr-2027 | E41: Jueves | F41: Clase
... B43: 16 | C43: =IF(OR(F43="FERIADO",F43="RECESO"),"—",ROWS($F$12:F43)-COUNTIF($F$12:F43,"FERIADO")-COUNTIF($F$12:F43,"RECESO")) -> 28 | D43: 29-abr-2027 | E43: Jueves | F43: Clase
B44: 17 | C44: =IF(OR(F44="FERIADO",F44="RECESO"),"—",ROWS($F$12:F44)-COUNTIF($F$12:F44,"FERIADO")-COUNTIF($F$12:F44,"RECESO")) -> 29 | D44: 04-may-2027 | E44: Martes | F44: Clase | I44: Evaluación docente ABIERTA (cierra 06-may-2027)
...

Sheet S1-Módulo 1
B1: ← Volver al índice
B2: S1 · Módulo 1 (presencial / semipresencial) | K2: RESUMEN DEL MÓDULO
B3: Lunes a jueves · 3 h diarias · 17-ago-2026 al 11-sep-2026. | K3: Sesiones de clase | L3: =COUNTIF(F12:F27,"Clase") -> 16
B4: Evaluación docente por parte de estudiantes (202610-G1): del 07-sep-2026 al 10-sep-2026 — cierra antes del último día de clase. | K4: Sesiones asincrónicas | L4: =COUNTIF(F12:F27,"Asincrónico") -> 0
K5: Días sin clase (feriado / receso) | L5: =COUNTIF(F12:F27,"FERIADO")+COUNTIF(F12:F27,"RECESO") -> 0
K6: Semanas | L6: =MAX(B12:B27) -> 4
K7: Evaluación docente | L7: ="07-sep-2026 al 10-sep-2026" -> 07-sep-2026 al 10-sep-2026
B11: Semana | C11: N° Sesión | D11: Fecha | E11: Día | F11: Estado | G11: Tema | H11: Entregas | I11: Observación
B12: 1 | C12: =IF(OR(F12="FERIADO",F12="RECESO"),"—",ROWS($F$12:F12)-COUNTIF($F$12:F12,"FERIADO")-COUNTIF($F$12:F12,"RECESO")) -> 1 | D12: 17-ago-2026 | E12: Lunes | F12: Clase | K12: FECHAS CLAVE
B13: 1 | C13: =IF(OR(F13="FERIADO",F13="RECESO"),"—",ROWS($F$12:F13)-COUNTIF($F$12:F13,"FERIADO")-COUNTIF($F$12:F13,"RECESO")) -> 2 | D13: 18-ago-2026 | E13: Martes | F13: Clase | K13: Último día para eliminar vía Banner | L13: 20-ago-2026
B14: 1 | C14: =IF(OR(F14="FERIADO",F14="RECESO"),"—",ROWS($F$12:F14)-COUNTIF($F$12:F14,"FERIADO")-COUNTIF($F$12:F14,"RECESO")) -> 3 | D14: 19-ago-2026 | E14: Miércoles | F14: Clase | K14: Retiro con W | L14: 21-ago-2026 a 28-ago-2026
B15: 1 | C15: =IF(OR(F15="FERIADO",F15="RECESO"),"—",ROWS($F$12:F15)-COUNTIF($F$12:F15,"FERIADO")-COUNTIF($F$12:F15,"RECESO")) -> 4 | D15: 20-ago-2026 | E15: Jueves | F15: Clase | K15: Evaluación docente | L15: 31-ago-2026 a 11-sep-2026
B16: 2 | C16: =IF(OR(F16="FERIADO",F16="RECESO"),"—",ROWS($F$12:F16)-COUNTIF($F$12:F16,"FERIADO")-COUNTIF($F$12:F16,"RECESO")) -> 5 | D16: 24-ago-2026 | E16: Lunes | F16: Clase | K16: Ingreso de calificaciones | L16: 21-sep-2026
B17: 2 | C17: =IF(OR(F17="FERIADO",F17="RECESO"),"—",ROWS($F$12:F17)-COUNTIF($F$12:F17,"FERIADO")-COUNTIF($F$12:F17,"RECESO")) -> 6 | D17: 25-ago-2026 | E17: Martes | F17: Clase
B18: 2 | C18: =IF(OR(F18="FERIADO",F18="RECESO"),"—",ROWS($F$12:F18)-COUNTIF($F$12:F18,"FERIADO")-COUNTIF($F$12:F18,"RECESO")) -> 7 | D18: 26-ago-2026 | E18: Miércoles | F18: Clase
B19: 2 | C19: =IF(OR(F19="FERIADO",F19="RECESO"),"—",ROWS($F$12:F19)-COUNTIF($F$12:F19,"FERIADO")-COUNTIF($F$12:F19,"RECESO")) -> 8 | D19: 27-ago-2026 | E19: Jueves | F19: Clase
B20: 3 | C20: =IF(OR(F20="FERIADO",F20="RECESO"),"—",ROWS($F$12:F20)-COUNTIF($F$12:F20,"FERIADO")-COUNTIF($F$12:F20,"RECESO")) -> 9 | D20: 31-ago-2026 | E20: Lunes | F20: Clase
B21: 3 | C21: =IF(OR(F21="FERIADO",F21="RECESO"),"—",ROWS($F$12:F21)-COUNTIF($F$12:F21,"FERIADO")-COUNTIF($F$12:F21,"RECESO")) -> 10 | D21: 01-sep-2026 | E21: Martes | F21: Clase
B22: 3 | C22: =IF(OR(F22="FERIADO",F22="RECESO"),"—",ROWS($F$12:F22)-COUNTIF($F$12:F22,"FERIADO")-COUNTIF($F$12:F22,"RECESO")) -> 11 | D22: 02-sep-2026 | E22: Miércoles | F22: Clase
B23: 3 | C23: =IF(OR(F23="FERIADO",F23="RECESO"),"—",ROWS($F$12:F23)-COUNTIF($F$12:F23,"FERIADO")-COUNTIF($F$12:F23,"RECESO")) -> 12 | D23: 03-sep-2026 | E23: Jueves | F23: Clase
B24: 4 | C24: =IF(OR(F24="FERIADO",F24="RECESO"),"—",ROWS($F$12:F24)-COUNTIF($F$12:F24,"FERIADO")-COUNTIF($F$12:F24,"RECESO")) -> 13 | D24: 07-sep-2026 | E24: Lunes | F24: Clase | I24: Evaluación docente ABIERTA (cierra 10-sep-2026)
B25: 4 | C25: =IF(OR(F25="FERIADO",F25="RECESO"),"—",ROWS($F$12:F25)-COUNTIF($F$12:F25,"FERIADO")-COUNTIF($F$12:F25,"RECESO")) -> 14 | D25: 08-sep-2026 | E25: Martes | F25: Clase | I25: Evaluación docente ABIERTA (cierra 10-sep-2026)
B26: 4 | C26: =IF(OR(F26="FERIADO",F26="RECESO"),"—",ROWS($F$12:F26)-COUNTIF($F$12:F26,"FERIADO")-COUNTIF($F$12:F26,"RECESO")) -> 15 | D26: 09-sep-2026 | E26: Miércoles | F26: Clase | I26: Evaluación docente ABIERTA (cierra 10-sep-2026)
B27: 4 | C27: =IF(OR(F27="FERIADO",F27="RECESO"),"—",ROWS($F$12:F27)-COUNTIF($F$12:F27,"FERIADO")-COUNTIF($F$12:F27,"RECESO")) -> 16 | D27: 10-sep-2026 | E27: Jueves | F27: Clase | I27: Última sesión del módulo · Evaluación docente ABIERTA (cierra 10-sep-2026)

Sheet S1-Módulo 2
B1: ← Volver al índice
B2: S1 · Módulo 2 (presencial / semipresencial) | K2: RESUMEN DEL MÓDULO
B3: Lunes a jueves · 3 h diarias · 14-sep-2026 al 09-oct-2026. | K3: Sesiones de clase | L3: =COUNTIF(F12:F27,"Clase") -> 16
B4: Evaluación docente por parte de estudiantes (202610-G2): del 05-oct-2026 al 07-oct-2026 — cierra antes del último día de clase. | K4: Sesiones asincrónicas | L4: =COUNTIF(F12:F27,"Asincrónico") -> 0
K5: Días sin clase (feriado / receso) | L5: =COUNTIF(F12:F27,"FERIADO")+COUNTIF(F12:F27,"RECESO") -> 0
K6: Semanas | L6: =MAX(B12:B27) -> 4
K7: Evaluación docente | L7: ="05-oct-2026 al 07-oct-2026" -> 05-oct-2026 al 07-oct-2026
B11: Semana | C11: N° Sesión | D11: Fecha | E11: Día | F11: Estado | G11: Tema | H11: Entregas | I11: Observación
